#include <iostream>
#include <exception>
using namespace std;


int main() {
    int numerador, denominador, resultado;


    cout << "Ingrese el numerador: ";
    cin >> numerador;
    cout << "Ingrese el denominador: ";
    cin >> denominador;


    try {
        // Intentamos realizar la divisi贸n
        if (denominador == 0) {
            throw runtime_error("Error: Divisi贸n por cero.");
        }
        resultado = numerador / denominador;
        cout << "El resultado es: " << resultado << endl;
    }
    catch (const exception& e) {
        // Capturamos la excepci贸n y mostramos el mensaje de error
        cerr << "Excepci贸n capturada: " << e.what() << endl;
    }


    return 0;
}
